Workbook

Sheet Raw Data
A1: =_xll.Thomson.Reuters.AFOSpreadSheetFormulas.DSGRID("TOTMKUS(PE),TRUS10T(RY),USCONPRCE, TOTMKUS(PI)/TOTMKUS(PE),TRUS3MT(RY)"," ","1973-01-31","","M","RowHeader=true;ColHeader=true;Heading=true;Curn=true;DispSeriesDescription=false;YearlyTSFormat=false;QuarterlyTSFormat=false","") -> #NAME? | B1: 26695
A2: End | B2: 45762
A3: Frequency | B3: M
A4: Name | B4: US-DS Market - PER | C4: US GVT EVAL BMK BID YLD 10Y - RED. YIELD | D4: US CPI - ALL URBAN: ALL ITEMS SADJ | E4: TOTMKUS(PI)/TOTMKUS(PE) | F4: US GVT EVAL BMK BID YLD 3M - RED. YIELD | H4: 12M FWD E | I4: Real Yield | J4: Steepness
A5: CURRENCY | B5: U$ | C5: U$ | D5: U$ | E5: U$ | F5: U$
A6: 26695 | B6: 23.6 | C6: 6.54 | D6: 42.7 | E6: 4.14 | F6: 5.68
A7: 26723 | B7: 22.8 | C7: 6.64 | D7: 43 | E7: 4.14 | F7: 5.85
A8: 26753 | B8: 22.7 | C8: 6.73 | D8: 43.4 | E8: 4.15 | F8: 6.4
A9: 26784 | B9: 21.6 | C9: 6.7 | D9: 43.7 | E9: 4.17 | F9: 6.23
A10: 26815 | B10: 20.7 | C10: 6.93 | D10: 43.9 | E10: 4.29 | F10: 6.92
A11: 26844 | B11: 20.6 | C11: 6.94 | D11: 44.2 | E11: 4.31 | F11: 7.52
A12: 26876 | B12: 21.4 | C12: 7.43 | D12: 44.2 | E12: 4.32 | F12: 8.32
A13: 26907 | B13: 20.5 | C13: 7.25 | D13: 45 | E13: 4.33 | F13: 8.66
A14: 26935 | B14: 21 | C14: 6.9 | D14: 45.2 | E14: 4.33 | F14: 6.98
A15: 26968 | B15: 20.8 | C15: 6.71 | D15: 45.6 | E15: 4.34 | F15: 7.36
A16: 26998 | B16: 18.4 | C16: 6.69 | D16: 45.9 | E16: 4.35 | F16: 7.3
A17: 27029 | B17: 18 | C17: 6.9 | D17: 46.3 | E17: 4.45 | F17: 7.46
... A125: 30316 | B125: 10.3 | C125: 10.36 | D125: 97.7 | E125: 10.79 | F125: 7.92
A126: 30347 | B126: 10.6 | C126: 10.8 | D126: 97.9 | E126: 10.79 | F126: 8.1 | H126: =G138 -> 0.12140871 | I126: =C126%-((D126/D6)^(1/10)-1) -> 0.021485612 | J126: =(C126-F126)% -> 0.027
A127: 30375 | B127: 10.8 | C127: 10.27 | D127: 98 | E127: 10.8 | F127: 7.93 | H127: =G139 -> 0.12314815 | I127: =C127%-((D127/D7)^(1/10)-1) -> 0.016835183 | J127: =(C127-F127)% -> 0.0234
A128: 30406 | B128: 11.1 | C128: 10.62 | D128: 98.1 | E128: 10.82 | F128: 8.64 | H128: =G140 -> 0.1219963 | I128: =C128%-((D128/D8)^(1/10)-1) -> 0.021229506 | J128: =(C128-F128)% -> 0.0198
A129: 30435 | B129: 11.9 | C129: 10.27 | D129: 98.8 | E129: 10.81 | F129: 8.08 | H129: =G141 -> 0.18316374 | I129: =C129%-((D129/D9)^(1/10)-1) -> 0.017705465 | J129: =(C129-F129)% -> 0.0219
A130: 30467 | B130: 11.6 | C130: 10.81 | D130: 99.2 | E130: 10.82 | F130: 8.63 | H130: =G142 -> 0.20425139 | I130: =C130%-((D130/D10)^(1/10)-1) -> 0.023162513 | J130: =(C130-F130)% -> 0.0218
A131: 30497 | B131: 11.7 | C131: 10.96 | D131: 99.4 | E131: 11.09 | F131: 8.79 | H131: =G143 -> 0.17493237 | I131: =C131%-((D131/D11)^(1/10)-1) -> 0.025182765 | J131: =(C131-F131)% -> 0.0217
A132: 30526 | B132: 11.3 | C132: 11.76 | D132: 99.8 | E132: 11.09 | F132: 9.22 | H132: =G144 -> 0.21731289 | I132: =C132%-((D132/D12)^(1/10)-1) -> 0.032747168 | J132: =(C132-F132)% -> 0.0254
A133: 30559 | B133: 11.4 | C133: 11.98 | D133: 100.1 | E133: 11.12 | F133: 9.26 | H133: =G145 -> 0.21492806 | I133: =C133%-((D133/D13)^(1/10)-1) -> 0.036566316 | J133: =(C133-F133)% -> 0.0272
A134: 30589 | B134: 11.3 | C134: 11.44 | D134: 100.4 | E134: 11.45 | F134: 8.71 | H134: =G146 -> 0.17991266 | I134: =C134%-((D134/D14)^(1/10)-1) -> 0.031322515 | J134: =(C134-F134)% -> 0.0273
A135: 30620 | B135: 11.1 | C135: 11.74 | D135: 100.8 | E135: 11.48 | F135: 8.51 | H135: =G147 -> 0.18902439 | I135: =C135%-((D135/D15)^(1/10)-1) -> 0.034846 | J135: =(C135-F135)% -> 0.0323
A136: 30650 | B136: 11.2 | C136: 11.63 | D136: 101.1 | E136: 11.56 | F136: 8.88 | H136: =G148 -> 0.1816609 | I136: =C136%-((D136/D16)^(1/10)-1) -> 0.034134095 | J136: =(C136-F136)% -> 0.0275
A137: 30680 | B137: 11.1 | C137: 11.82 | D137: 101.4 | E137: 11.6 | F137: 8.97 | H137: =G149 -> 0.17327586 | I137: =C137%-((D137/D17)^(1/10)-1) -> 0.036652254 | J137: =(C137-F137)% -> 0.0285
A138: 30712 | B138: 10.5 | C138: 11.67 | D138: 102.1 | E138: 12.1 | F138: 8.89 | G138: =E138/E126-1 -> 0.12140871 | H138: =G150 -> 0.12561983 | I138: =C138%-((D138/D18)^(1/10)-1) -> 0.035569825 | J138: =(C138-F138)% -> 0.0278
A139: 30741 | B139: 10 | C139: 12.04 | D139: 102.6 | E139: 12.13 | F139: 9.14 | G139: =E139/E127-1 -> 0.12314815 | H139: =G151 -> 0.11624073 | I139: =C139%-((D139/D19)^(1/10)-1) -> 0.039890419 | J139: =(C139-F139)% -> 0.029
A140: 30771 | B140: 10.1 | C140: 12.53 | D140: 102.9 | E140: 12.14 | F140: 9.72 | G140: =E140/E128-1 -> 0.1219963 | H140: =G152 -> 0.11449753 | I140: =C140%-((D140/D20)^(1/10)-1) -> 0.045610823 | J140: =(C140-F140)% -> 0.0281
A141: 30802 | B141: 9.6 | C141: 12.82 | D141: 103.3 | E141: 12.79 | F141: 9.72 | G141: =E141/E129-1 -> 0.18316374 | H141: =G153 -> 0.038311181 | I141: =C141%-((D141/D21)^(1/10)-1) -> 0.048767414 | J141: =(C141-F141)% -> 0.031
A142: 30833 | B142: 8.9 | C142: 13.91 | D142: 103.5 | E142: 13.03 | F142: 9.75 | G142: =E142/E130-1 -> 0.20425139 | H142: =G154 -> 0.010744436 | I142: =C142%-((D142/D22)^(1/10)-1) -> 0.060574524 | J142: =(C142-F142)% -> 0.0416
A143: 30862 | B143: 9.1 | C143: 13.84 | D143: 103.7 | E143: 13.03 | F143: 9.92 | G143: =E143/E131-1 -> 0.17493237 | H143: =G155 -> 0.011511896 | I143: =C143%-((D143/D23)^(1/10)-1) -> 0.060550145 | J143: =(C143-F143)% -> 0.0392
A144: 30894 | B144: 8.7 | C144: 12.91 | D144: 104.1 | E144: 13.5 | F144: 10.4 | G144: =E144/E132-1 -> 0.21731289 | H144: =G156 -> -0.034074074 | I144: =C144%-((D144/D24)^(1/10)-1) -> 0.051493057 | J144: =(C144-F144)% -> 0.0251
A145: 30925 | B145: 9.6 | C145: 12.79 | D145: 104.4 | E145: 13.51 | F145: 10.63 | G145: =E145/E133-1 -> 0.21492806 | H145: =G157 -> -0.035529238 | I145: =C145%-((D145/D25)^(1/10)-1) -> 0.051286069 | J145: =(C145-F145)% -> 0.0216
A146: 30953 | B146: 9.6 | C146: 12.47 | D146: 104.7 | E146: 13.51 | F146: 10.22 | G146: =E146/E134-1 -> 0.17991266 | H146: =G158 -> -0.049592894 | I146: =C146%-((D146/D26)^(1/10)-1) -> 0.049276267 | J146: =(C146-F146)% -> 0.0225
A147: 30986 | B147: 9.5 | C147: 11.79 | D147: 105.1 | E147: 13.65 | F147: 9.01 | G147: =E147/E135-1 -> 0.18902439 | H147: =G159 -> -0.059340659 | I147: =C147%-((D147/D27)^(1/10)-1) -> 0.042912897 | J147: =(C147-F147)% -> 0.0278
...

Sheet US MKT
B1: ='Raw Data'!I4 -> Real Yield | C1: ='Raw Data'!B4 -> US-DS Market - PER | D1: ='Raw Data'!H4 -> 12M FWD E
A2: ='Raw Data'!A127 -> 30375 | B2: ='Raw Data'!I127 -> 0.016835183 | C2: ='Raw Data'!B127 -> 10.8 | D2: ='Raw Data'!H127 -> 0.12314815
A3: ='Raw Data'!A128 -> 30406 | B3: ='Raw Data'!I128 -> 0.021229506 | C3: ='Raw Data'!B128 -> 11.1 | D3: ='Raw Data'!H128 -> 0.1219963
A4: ='Raw Data'!A129 -> 30435 | B4: ='Raw Data'!I129 -> 0.017705465 | C4: ='Raw Data'!B129 -> 11.9 | D4: ='Raw Data'!H129 -> 0.18316374
A5: ='Raw Data'!A130 -> 30467 | B5: ='Raw Data'!I130 -> 0.023162513 | C5: ='Raw Data'!B130 -> 11.6 | D5: ='Raw Data'!H130 -> 0.20425139
A6: ='Raw Data'!A131 -> 30497 | B6: ='Raw Data'!I131 -> 0.025182765 | C6: ='Raw Data'!B131 -> 11.7 | D6: ='Raw Data'!H131 -> 0.17493237
A7: ='Raw Data'!A132 -> 30526 | B7: ='Raw Data'!I132 -> 0.032747168 | C7: ='Raw Data'!B132 -> 11.3 | D7: ='Raw Data'!H132 -> 0.21731289
A8: ='Raw Data'!A133 -> 30559 | B8: ='Raw Data'!I133 -> 0.036566316 | C8: ='Raw Data'!B133 -> 11.4 | D8: ='Raw Data'!H133 -> 0.21492806
A9: ='Raw Data'!A134 -> 30589 | B9: ='Raw Data'!I134 -> 0.031322515 | C9: ='Raw Data'!B134 -> 11.3 | D9: ='Raw Data'!H134 -> 0.17991266
A10: ='Raw Data'!A135 -> 30620 | B10: ='Raw Data'!I135 -> 0.034846 | C10: ='Raw Data'!B135 -> 11.1 | D10: ='Raw Data'!H135 -> 0.18902439
A11: ='Raw Data'!A136 -> 30650 | B11: ='Raw Data'!I136 -> 0.034134095 | C11: ='Raw Data'!B136 -> 11.2 | D11: ='Raw Data'!H136 -> 0.1816609
A12: ='Raw Data'!A137 -> 30680 | B12: ='Raw Data'!I137 -> 0.036652254 | C12: ='Raw Data'!B137 -> 11.1 | D12: ='Raw Data'!H137 -> 0.17327586
A13: ='Raw Data'!A138 -> 30712 | B13: ='Raw Data'!I138 -> 0.035569825 | C13: ='Raw Data'!B138 -> 10.5 | D13: ='Raw Data'!H138 -> 0.12561983
... A495: ='Raw Data'!A620 -> 45380 | B495: ='Raw Data'!I620 -> 0.013726466 | C495: ='Raw Data'!B620 -> 26.9 | D495: ='Raw Data'!H620 -> 0.10024141
